Workbook

Sheet How to use
A1: Opencast Pit Planning & Economics Study — advanced workbook
A2: Built so you can see exactly how every number is calculated. Change the yellow cells and everything else recalculates.
A4: IMPORTANT — about the numbers
A5: All values here are made-up SAMPLE values chosen for demonstration (typical ranges, not data from any real mine). Replace them with figures from your textbook problem, published reports or your own measurements. Do not use confidential mine data without permission. Add this project to your resume only after you can explain every sheet.
A7: What question does each sheet answer?
A8: • Inputs — all assumptions in one place: block size, densities, machine specs, costs, coal price, and the settings for the advanced sheets.
A9: • Reserve — how much coal and overburden is in the pit, and which blocks are worth mining (block / borehole-grid method).
A10: • Geostatistics — how continuous the seam is (semivariogram) and the kriged thickness, with a 95 % confidence interval, at any point.
A11: • Pit design — bench and overall slope geometry, the extra wall rock (slope wedge) added to the stripping ratio, and the planar-failure factor of safety.
A12: • Fleet — how many excavators and dumpers are needed to reach the production target.
A13: • Safety — blast ground vibration against DGMS limits, and the stopping distance of a loaded dumper on the ramp.
A14: • Quality and royalty — washability (float-and-sink) yield, whether washing pays, and the statutory levies: royalty, DMF and NMET.
... A54: Royalty on coal is 14 % ad valorem (MMDR Act 1957, Second Schedule; GSR 349(E) of 10 May 2012). DMF is 30 % of royalty for leases granted before 12 January 2015 and 10 % after. NMET at 2 % and the other-levy figure are placeholders to verify. Permissible PPV values are from DGMS (Tech)(S&T) Circular No. 7 of 1997. Check current notifications before relying on any of them.

Sheet Inputs
A1: Inputs — every assumption in one place
A2: SAMPLE VALUES chosen by Claude for demonstration (typical ranges, not from any real mine). Replace the yellow cells with your textbook / published data. Sections 6 to 12 drive the advanced sheets.
A4: Parameter | B4: Value | C4: Unit | D4: What it means / typical range
A5: 1. Block model and production target
A6: Block length | B6: 100 | C6: m | D6: Each block is the area of influence of one borehole (grid spacing).
A7: Block width | B7: 100 | C7: m | D7: Same idea, other direction. Block area = length × width.
A8: Coal relative density | B8: 1.4 | C8: t/m³ | D8: Typical Indian non-coking coal about 1.3 to 1.6.
A9: Overburden density in the bank | B9: 2.2 | C9: t/BCM | D9: BCM = bank cubic metre (rock measured before blasting). Sandstone/shale mix about 2.0 to 2.5.
A10: Mining recovery | B10: 0.92 | C10: fraction | D10: Share of coal in place that is actually produced (losses at roof, floor, edges). Typical 0.90 to 0.95.
A11: Annual coal production target | B11: 500000 | C11: t/year | D11: Target the fleet must achieve each year.
A12: 2. Excavator
A13: Bucket capacity | B13: 4 | C13: m³ (heaped) | D13: Rated bucket size of the hydraulic excavator.
A14: Bucket fill factor | B14: 0.85 | C14: fraction | D14: How full the bucket really is. Typical 0.75 to 0.95.
A15: Swell factor, overburden | B15: 1.35 | C15: loose ÷ bank | D15: Blasted rock occupies more volume than in the bank. Typical 1.25 to 1.50.
A16: Swell factor, coal | B16: 1.3 | C16: loose ÷ bank | D16: Typical 1.20 to 1.40.
A17: Excavator cycle time | B17: 30 | C17: seconds | D17: Dig, swing, dump, return for one bucket. Typical 25 to 35 s.
A18: Excavator job efficiency | B18: 50 | C18: min per hour | D18: Productive minutes in each hour after small delays. Typical 45 to 55.
A19: 3. Dumpers and haul route
A20: Dumper rated payload | B20: 35 | C20: t | D20: Maximum load per trip.
A21: Haul distance, overburden to dump | B21: 2 | C21: km one way | D21: Distance from pit face to external or internal dump.
A22: Haul distance, coal to stockyard | B22: 3 | C22: km one way | D22: Distance from pit face to coal stockyard.
A23: Average loaded speed | B23: 20 | C23: km/h | D23: Slower than empty because of ramp gradient and rolling resistance.
A24: Average empty speed | B24: 28 | C24: km/h | D24: Returning empty.
A25: Spotting time at excavator | B25: 0.7 | C25: min | D25: Dumper positions itself under the bucket.
A26: Dumping and manoeuvring time | B26: 1.3 | C26: min | D26: Reverse, tip, pull away.
A27: Dumper job efficiency | B27: 50 | C27: min per hour | D27: Productive minutes in each hour.
A28: 4. Working time
A29: Working days per year | B29: 330 | C29: days | D29: Calendar days minus holidays and monsoon stoppages.
A30: Shifts per day | B30: 3 | C30: shifts
A31: Hours per shift | B31: 8 | C31: hours
A32: Machine availability | B32: 0.85 | C32: fraction | D32: Share of time the machine is mechanically ready.
A33: Machine utilisation | B33: 0.8 | C33: fraction | D33: Share of available time the machine is actually working.
A34: 5. Costs, price and capital
A35: Drilling and blasting, overburden | B35: 35 | C35: ₹/BCM | D35: Link this to your Blast Design Calculator cost estimate later.
A36: Drilling and blasting, coal | B36: 20 | C36: ₹/t
A37: Excavator hourly cost | B37: 4500 | C37: ₹/hour | D37: Ownership + fuel + operator + maintenance, for one hour.
A38: Dumper hourly cost | B38: 3000 | C38: ₹/hour | D38: Same idea for one dumper.
A39: Coal handling and dispatch | B39: 150 | C39: ₹/t | D39: Crushing, loading to trucks or rail, weighing.
A40: Overheads and other site costs | B40: 600 | C40: ₹/t | D40: Supervision, dewatering, power, admin, safety.
A41: Royalty and statutory levies | B41: 900 | C41: ₹/t | D41: Check the current statutory rates; this is only a placeholder.
...

Sheet Reserve
A1: Reserve — how much coal and overburden, and which blocks are worth mining?
A2: Block (borehole-grid) method: each borehole represents one block. Enter thickness from each borehole; everything else is formula. SAMPLE DATA.
A5: Block | B5: Overburden thickness (m) | C5: Coal seam thickness (m) | D5: Block area (m²) | E5: Overburden volume (BCM) | F5: Coal volume (m³) | G5: Coal in place (t) | H5: Stripping ratio (m³/t) | I5: Economic to mine? (SR ≤ break-even)
A6: A1 | B6: 18 | C6: 8.5 | D6: =Inputs!$B$6*Inputs!$B$7 -> 10000 | E6: =D6*B6 -> 180000 | F6: =D6*C6 -> 85000 | G6: =F6*Inputs!$B$8 -> 119000 | H6: =IFERROR(E6/G6,0) -> 1.512605 | I6: =IF(H6<=Economics!$B$21,"Yes","No") -> Yes
A7: A2 | B7: 23 | C7: 8 | D7: =Inputs!$B$6*Inputs!$B$7 -> 10000 | E7: =D7*B7 -> 230000 | F7: =D7*C7 -> 80000 | G7: =F7*Inputs!$B$8 -> 112000 | H7: =IFERROR(E7/G7,0) -> 2.0535714 | I7: =IF(H7<=Economics!$B$21,"Yes","No") -> Yes
A8: A3 | B8: 29 | C8: 7.5 | D8: =Inputs!$B$6*Inputs!$B$7 -> 10000 | E8: =D8*B8 -> 290000 | F8: =D8*C8 -> 75000 | G8: =F8*Inputs!$B$8 -> 105000 | H8: =IFERROR(E8/G8,0) -> 2.7619048 | I8: =IF(H8<=Economics!$B$21,"Yes","No") -> Yes
A9: A4 | B9: 36 | C9: 7 | D9: =Inputs!$B$6*Inputs!$B$7 -> 10000 | E9: =D9*B9 -> 360000 | F9: =D9*C9 -> 70000 | G9: =F9*Inputs!$B$8 -> 98000 | H9: =IFERROR(E9/G9,0) -> 3.6734694 | I9: =IF(H9<=Economics!$B$21,"Yes","No") -> Yes
A10: A5 | B10: 45 | C10: 6.5 | D10: =Inputs!$B$6*Inputs!$B$7 -> 10000 | E10: =D10*B10 -> 450000 | F10: =D10*C10 -> 65000 | G10: =F10*Inputs!$B$8 -> 91000 | H10: =IFERROR(E10/G10,0) -> 4.9450549 | I10: =IF(H10<=Economics!$B$21,"Yes","No") -> No
A11: B1 | B11: 20 | C11: 9 | D11: =Inputs!$B$6*Inputs!$B$7 -> 10000 | E11: =D11*B11 -> 200000 | F11: =D11*C11 -> 90000 | G11: =F11*Inputs!$B$8 -> 126000 | H11: =IFERROR(E11/G11,0) -> 1.5873016 | I11: =IF(H11<=Economics!$B$21,"Yes","No") -> Yes
A12: B2 | B12: 25 | C12: 8.5 | D12: =Inputs!$B$6*Inputs!$B$7 -> 10000 | E12: =D12*B12 -> 250000 | F12: =D12*C12 -> 85000 | G12: =F12*Inputs!$B$8 -> 119000 | H12: =IFERROR(E12/G12,0) -> 2.1008403 | I12: =IF(H12<=Economics!$B$21,"Yes","No") -> Yes
A13: B3 | B13: 31 | C13: 8 | D13: =Inputs!$B$6*Inputs!$B$7 -> 10000 | E13: =D13*B13 -> 310000 | F13: =D13*C13 -> 80000 | G13: =F13*Inputs!$B$8 -> 112000 | H13: =IFERROR(E13/G13,0) -> 2.7678571 | I13: =IF(H13<=Economics!$B$21,"Yes","No") -> Yes
A14: B4 | B14: 38 | C14: 7.5 | D14: =Inputs!$B$6*Inputs!$B$7 -> 10000 | E14: =D14*B14 -> 380000 | F14: =D14*C14 -> 75000 | G14: =F14*Inputs!$B$8 -> 105000 | H14: =IFERROR(E14/G14,0) -> 3.6190476 | I14: =IF(H14<=Economics!$B$21,"Yes","No") -> Yes
A15: B5 | B15: 47 | C15: 6.5 | D15: =Inputs!$B$6*Inputs!$B$7 -> 10000 | E15: =D15*B15 -> 470000 | F15: =D15*C15 -> 65000 | G15: =F15*Inputs!$B$8 -> 91000 | H15: =IFERROR(E15/G15,0) -> 5.1648352 | I15: =IF(H15<=Economics!$B$21,"Yes","No") -> No
A16: C1 | B16: 19 | C16: 9.5 | D16: =Inputs!$B$6*Inputs!$B$7 -> 10000 | E16: =D16*B16 -> 190000 | F16: =D16*C16 -> 95000 | G16: =F16*Inputs!$B$8 -> 133000 | H16: =IFERROR(E16/G16,0) -> 1.4285714 | I16: =IF(H16<=Economics!$B$21,"Yes","No") -> Yes
A17: C2 | B17: 24 | C17: 9 | D17: =Inputs!$B$6*Inputs!$B$7 -> 10000 | E17: =D17*B17 -> 240000 | F17: =D17*C17 -> 90000 | G17: =F17*Inputs!$B$8 -> 126000 | H17: =IFERROR(E17/G17,0) -> 1.9047619 | I17: =IF(H17<=Economics!$B$21,"Yes","No") -> Yes
... A25: D5 | B25: 43 | C25: 6 | D25: =Inputs!$B$6*Inputs!$B$7 -> 10000 | E25: =D25*B25 -> 430000 | F25: =D25*C25 -> 60000 | G25: =F25*Inputs!$B$8 -> 84000 | H25: =IFERROR(E25/G25,0) -> 5.1190476 | I25: =IF(H25<=Economics!$B$21,"Yes","No") -> No
A26: Total / overall | B26: =AVERAGE(B6:B25) -> 30.55 | C26: =AVERAGE(C6:C25) -> 7.875 | D26: =SUM(D6:D25) -> 200000 | E26: =SUM(E6:E25) -> 6110000 | F26: =SUM(F6:F25) -> 1575000 | G26: =SUM(G6:G25) -> 2205000 | H26: =IFERROR(E26/G26,0) -> 2.7709751 | I26: =COUNTIF(I6:I25,"Yes")&" of "&COUNTA(A6:A25)&" blocks" -> 16 of 20 blocks
A27: Row 26: thickness columns show the average; other columns show totals. Overall stripping ratio = total overburden ÷ total coal.
A28: All blocks
A29: Coal in place | B29: =G26 -> 2205000 | C29: t | D29: Sum of all block tonnages.
A30: Recoverable coal | B30: =B29*Inputs!$B$10 -> 2028600 | C30: t | D30: Coal in place × mining recovery.
A31: Overall stripping ratio | B31: =H26 -> 2.7709751 | C31: m³/t | D31: Total overburden ÷ total coal in place.
A32: Mine life, all blocks | B32: =B30/Inputs!$B$11 -> 4.0572 | C32: years | D32: Recoverable coal ÷ annual production.
A33: Economic blocks only (stripping ratio at or below the break-even)
A34: Mining a block above the break-even loses money, so the plan keeps only the 'Yes' blocks. This is the idea behind a pit limit.
A35: Number of economic blocks | B35: =COUNTIF(I6:I25,"Yes") -> 16 | C35: blocks | D35: Blocks marked Yes.
A36: Coal in place, economic blocks | B36: =SUMIF(I6:I25,"Yes",G6:G25) -> 1841000 | C36: t | D36: SUMIF over the Yes blocks.
A37: Overburden, economic blocks | B37: =SUMIF(I6:I25,"Yes",E6:E25) -> 4320000 | C37: BCM | D37: SUMIF over the Yes blocks.
A38: Stripping ratio, economic blocks | B38: ='Pit design'!$B$37 -> 2.9310858 | C38: m³/t | D38: Includes the pit-slope wedge when the switch on Inputs is 1 (Pit design sheet). Used by the Fleet and Economics sheets.
A39: Recoverable coal, economic blocks | B39: =B36*Inputs!$B$10 -> 1693720 | C39: t | D39: Used for mine life and the cash flow.
A40: Mine life, economic blocks | B40: =B39/Inputs!$B$11 -> 3.38744 | C40: years | D40: Recoverable coal ÷ annual production.

Sheet Geostatistics
A1: Geostatistics — how continuous is the seam, and what is the kriged estimate at an unsampled point?
A2: Semivariogram of the borehole thicknesses, a fitted model, and ordinary kriging with a 95 % confidence interval. SAMPLE DATA: replace the boreholes on the Reserve sheet.
A4: A. Borehole data and trend surface
A5: Block | B5: X (m) | C5: Y (m) | D5: Coal seam thickness (m) | E5: Overburden thickness (m) | F5: Coal trend (m) | G5: Coal value used (m) | H5: Overburden trend (m) | I5: Overburden value used (m)
A6: =Reserve!A6 -> A1 | B6: =(VALUE(MID(A6,2,9))-0.5)*Inputs!$B$6 -> 50 | C6: =(CODE(UPPER(LEFT(A6,1)))-65+0.5)*Inputs!$B$7 -> 50 | D6: =Reserve!C6 -> 8.5 | E6: =Reserve!B6 -> 18 | F6: =IF(Inputs!$B$50=1,$B$29+$C$29*B6+$D$29*C6,0) -> 8.935 | G6: =D6-F6 -> -0.435 | H6: =IF(Inputs!$B$50=1,$B$30+$C$30*B6+$D$30*C6,0) -> 18.2 | I6: =E6-H6 -> -0.2
A7: =Reserve!A7 -> A2 | B7: =(VALUE(MID(A7,2,9))-0.5)*Inputs!$B$6 -> 150 | C7: =(CODE(UPPER(LEFT(A7,1)))-65+0.5)*Inputs!$B$7 -> 50 | D7: =Reserve!C7 -> 8 | E7: =Reserve!B7 -> 23 | F7: =IF(Inputs!$B$50=1,$B$29+$C$29*B7+$D$29*C7,0) -> 8.3225 | G7: =D7-F7 -> -0.3225 | H7: =IF(Inputs!$B$50=1,$B$30+$C$30*B7+$D$30*C7,0) -> 24.75 | I7: =E7-H7 -> -1.75
A8: =Reserve!A8 -> A3 | B8: =(VALUE(MID(A8,2,9))-0.5)*Inputs!$B$6 -> 250 | C8: =(CODE(UPPER(LEFT(A8,1)))-65+0.5)*Inputs!$B$7 -> 50 | D8: =Reserve!C8 -> 7.5 | E8: =Reserve!B8 -> 29 | F8: =IF(Inputs!$B$50=1,$B$29+$C$29*B8+$D$29*C8,0) -> 7.71 | G8: =D8-F8 -> -0.21 | H8: =IF(Inputs!$B$50=1,$B$30+$C$30*B8+$D$30*C8,0) -> 31.3 | I8: =E8-H8 -> -2.3
A9: =Reserve!A9 -> A4 | B9: =(VALUE(MID(A9,2,9))-0.5)*Inputs!$B$6 -> 350 | C9: =(CODE(UPPER(LEFT(A9,1)))-65+0.5)*Inputs!$B$7 -> 50 | D9: =Reserve!C9 -> 7 | E9: =Reserve!B9 -> 36 | F9: =IF(Inputs!$B$50=1,$B$29+$C$29*B9+$D$29*C9,0) -> 7.0975 | G9: =D9-F9 -> -0.0975 | H9: =IF(Inputs!$B$50=1,$B$30+$C$30*B9+$D$30*C9,0) -> 37.85 | I9: =E9-H9 -> -1.85
A10: =Reserve!A10 -> A5 | B10: =(VALUE(MID(A10,2,9))-0.5)*Inputs!$B$6 -> 450 | C10: =(CODE(UPPER(LEFT(A10,1)))-65+0.5)*Inputs!$B$7 -> 50 | D10: =Reserve!C10 -> 6.5 | E10: =Reserve!B10 -> 45 | F10: =IF(Inputs!$B$50=1,$B$29+$C$29*B10+$D$29*C10,0) -> 6.485 | G10: =D10-F10 -> 0.015 | H10: =IF(Inputs!$B$50=1,$B$30+$C$30*B10+$D$30*C10,0) -> 44.4 | I10: =E10-H10 -> 0.6
A11: =Reserve!A11 -> B1 | B11: =(VALUE(MID(A11,2,9))-0.5)*Inputs!$B$6 -> 50 | C11: =(CODE(UPPER(LEFT(A11,1)))-65+0.5)*Inputs!$B$7 -> 150 | D11: =Reserve!C11 -> 9 | E11: =Reserve!B11 -> 20 | F11: =IF(Inputs!$B$50=1,$B$29+$C$29*B11+$D$29*C11,0) -> 9.045 | G11: =D11-F11 -> -0.045 | H11: =IF(Inputs!$B$50=1,$B$30+$C$30*B11+$D$30*C11,0) -> 17.7 | I11: =E11-H11 -> 2.3
A12: =Reserve!A12 -> B2 | B12: =(VALUE(MID(A12,2,9))-0.5)*Inputs!$B$6 -> 150 | C12: =(CODE(UPPER(LEFT(A12,1)))-65+0.5)*Inputs!$B$7 -> 150 | D12: =Reserve!C12 -> 8.5 | E12: =Reserve!B12 -> 25 | F12: =IF(Inputs!$B$50=1,$B$29+$C$29*B12+$D$29*C12,0) -> 8.4325 | G12: =D12-F12 -> 0.0675 | H12: =IF(Inputs!$B$50=1,$B$30+$C$30*B12+$D$30*C12,0) -> 24.25 | I12: =E12-H12 -> 0.75
A13: =Reserve!A13 -> B3 | B13: =(VALUE(MID(A13,2,9))-0.5)*Inputs!$B$6 -> 250 | C13: =(CODE(UPPER(LEFT(A13,1)))-65+0.5)*Inputs!$B$7 -> 150 | D13: =Reserve!C13 -> 8 | E13: =Reserve!B13 -> 31 | F13: =IF(Inputs!$B$50=1,$B$29+$C$29*B13+$D$29*C13,0) -> 7.82 | G13: =D13-F13 -> 0.18 | H13: =IF(Inputs!$B$50=1,$B$30+$C$30*B13+$D$30*C13,0) -> 30.8 | I13: =E13-H13 -> 0.2
A14: =Reserve!A14 -> B4 | B14: =(VALUE(MID(A14,2,9))-0.5)*Inputs!$B$6 -> 350 | C14: =(CODE(UPPER(LEFT(A14,1)))-65+0.5)*Inputs!$B$7 -> 150 | D14: =Reserve!C14 -> 7.5 | E14: =Reserve!B14 -> 38 | F14: =IF(Inputs!$B$50=1,$B$29+$C$29*B14+$D$29*C14,0) -> 7.2075 | G14: =D14-F14 -> 0.2925 | H14: =IF(Inputs!$B$50=1,$B$30+$C$30*B14+$D$30*C14,0) -> 37.35 | I14: =E14-H14 -> 0.65
A15: =Reserve!A15 -> B5 | B15: =(VALUE(MID(A15,2,9))-0.5)*Inputs!$B$6 -> 450 | C15: =(CODE(UPPER(LEFT(A15,1)))-65+0.5)*Inputs!$B$7 -> 150 | D15: =Reserve!C15 -> 6.5 | E15: =Reserve!B15 -> 47 | F15: =IF(Inputs!$B$50=1,$B$29+$C$29*B15+$D$29*C15,0) -> 6.595 | G15: =D15-F15 -> -0.095 | H15: =IF(Inputs!$B$50=1,$B$30+$C$30*B15+$D$30*C15,0) -> 43.9 | I15: =E15-H15 -> 3.1
A16: =Reserve!A16 -> C1 | B16: =(VALUE(MID(A16,2,9))-0.5)*Inputs!$B$6 -> 50 | C16: =(CODE(UPPER(LEFT(A16,1)))-65+0.5)*Inputs!$B$7 -> 250 | D16: =Reserve!C16 -> 9.5 | E16: =Reserve!B16 -> 19 | F16: =IF(Inputs!$B$50=1,$B$29+$C$29*B16+$D$29*C16,0) -> 9.155 | G16: =D16-F16 -> 0.345 | H16: =IF(Inputs!$B$50=1,$B$30+$C$30*B16+$D$30*C16,0) -> 17.2 | I16: =E16-H16 -> 1.8
A17: =Reserve!A17 -> C2 | B17: =(VALUE(MID(A17,2,9))-0.5)*Inputs!$B$6 -> 150 | C17: =(CODE(UPPER(LEFT(A17,1)))-65+0.5)*Inputs!$B$7 -> 250 | D17: =Reserve!C17 -> 9 | E17: =Reserve!B17 -> 24 | F17: =IF(Inputs!$B$50=1,$B$29+$C$29*B17+$D$29*C17,0) -> 8.5425 | G17: =D17-F17 -> 0.4575 | H17: =IF(Inputs!$B$50=1,$B$30+$C$30*B17+$D$30*C17,0) -> 23.75 | I17: =E17-H17 -> 0.25
... A25: =Reserve!A25 -> D5 | B25: =(VALUE(MID(A25,2,9))-0.5)*Inputs!$B$6 -> 450 | C25: =(CODE(UPPER(LEFT(A25,1)))-65+0.5)*Inputs!$B$7 -> 350 | D25: =Reserve!C25 -> 6 | E25: =Reserve!B25 -> 43 | F25: =IF(Inputs!$B$50=1,$B$29+$C$29*B25+$D$29*C25,0) -> 6.815 | G25: =D25-F25 -> -0.815 | H25: =IF(Inputs!$B$50=1,$B$30+$C$30*B25+$D$30*C25,0) -> 42.9 | I25: =E25-H25 -> 0.1
A27: Trend surface: thickness = a + b × X + c × Y (least squares). Used only when the trend switch on Inputs is 1.
A28: Quantity | B28: a (intercept, m) | C28: b (m per m, X) | D28: c (m per m, Y) | E28: R²
A29: Coal seam thickness | B29: =INDEX(LINEST($D$6:$D$25,$B$6:$C$25,TRUE(),TRUE()),1,3) -> 9.18625 | C29: =INDEX(LINEST($D$6:$D$25,$B$6:$C$25,TRUE(),TRUE()),1,2) -> -0.006125 | D29: =INDEX(LINEST($D$6:$D$25,$B$6:$C$25,TRUE(),TRUE()),1,1) -> 0.0011 | E29: =INDEX(LINEST($D$6:$D$25,$B$6:$C$25,TRUE(),TRUE()),3,1) -> 0.85344948
A30: Overburden thickness | B30: =INDEX(LINEST($E$6:$E$25,$B$6:$C$25,TRUE(),TRUE()),1,3) -> 15.175 | C30: =INDEX(LINEST($E$6:$E$25,$B$6:$C$25,TRUE(),TRUE()),1,2) -> 0.0655 | D30: =INDEX(LINEST($E$6:$E$25,$B$6:$C$25,TRUE(),TRUE()),1,1) -> -0.005 | E30: =INDEX(LINEST($E$6:$E$25,$B$6:$C$25,TRUE(),TRUE()),3,1) -> 0.97808001
A32: B. Experimental semivariogram and the fitted model
A33: Lag class | B33: Nominal lag (m) | C33: Pairs | D33: Mean distance (m) | E33: Experimental γ (m²) | F33: Model γ (m²) | G33: Weighted squared error | I33: h (m) | J33: Model γ(h)
A34: 1 | B34: =A34*Inputs!$B$55 -> 100 | C34: =COUNTIFS($B$102:$U$121,">="&(B34-Inputs!$B$55/2),$B$102:$U$121,"<"&(B34+Inputs!$B$55/2))/2 -> 55 | D34: =IFERROR(AVERAGEIFS($B$102:$U$121,$B$102:$U$121,">="&(B34-Inputs!$B$55/2),$B$102:$U$121,"<"&(B34+Inputs!$B$55/2)),0) -> 118.07477 | E34: =IFERROR(AVERAGEIFS($B$125:$U$144,$B$102:$U$121,">="&(B34-Inputs!$B$55/2),$B$102:$U$121,"<"&(B34+Inputs!$B$55/2)),0) -> 0.12902864 | F34: =IF(D34=0,0,CHOOSE(Inputs!$B$51,IF(D34>=Inputs!$B$54,Inputs!$B$52+Inputs!$B$53,Inputs!$B$52+Inputs!$B$53*(1.5*D34/Inputs!$B$54-0.5*(D34/Inputs!$B$54)^3)),Inputs!$B$52+Inputs!$B$53*(1-EXP(-3*D34/Inputs!$B$54)),Inputs!$B$52+Inputs!$B$53*(1-EXP(-3*(D34/Inputs!$B$54)^2)))) -> 0.13478732 | G34: =C34*(E34-F34)^2 -> 0.0018239324 | I34: 0 | J34: =IF(I34=0,0,CHOOSE(Inputs!$B$51,IF(I34>=Inputs!$B$54,Inputs!$B$52+Inputs!$B$53,Inputs!$B$52+Inputs!$B$53*(1.5*I34/Inputs!$B$54-0.5*(I34/Inputs!$B$54)^3)),Inputs!$B$52+Inputs!$B$53*(1-EXP(-3*I34/Inputs!$B$54)),Inputs!$B$52+Inputs!$B$53*(1-EXP(-3*(I34/Inputs!$B$54)^2)))) -> 0
A35: 2 | B35: =A35*Inputs!$B$55 -> 200 | C35: =COUNTIFS($B$102:$U$121,">="&(B35-Inputs!$B$55/2),$B$102:$U$121,"<"&(B35+Inputs!$B$55/2))/2 -> 56 | D35: =IFERROR(AVERAGEIFS($B$102:$U$121,$B$102:$U$121,">="&(B35-Inputs!$B$55/2),$B$102:$U$121,"<"&(B35+Inputs!$B$55/2)),0) -> 214.3327 | E35: =IFERROR(AVERAGEIFS($B$125:$U$144,$B$102:$U$121,">="&(B35-Inputs!$B$55/2),$B$102:$U$121,"<"&(B35+Inputs!$B$55/2)),0) -> 0.15881652 | F35: =IF(D35=0,0,CHOOSE(Inputs!$B$51,IF(D35>=Inputs!$B$54,Inputs!$B$52+Inputs!$B$53,Inputs!$B$52+Inputs!$B$53*(1.5*D35/Inputs!$B$54-0.5*(D35/Inputs!$B$54)^3)),Inputs!$B$52+Inputs!$B$53*(1-EXP(-3*D35/Inputs!$B$54)),Inputs!$B$52+Inputs!$B$53*(1-EXP(-3*(D35/Inputs!$B$54)^2)))) -> 0.15 | G35: =C35*(E35-F35)^2 -> 0.0043529353 | I35: 50 | J35: =IF(I35=0,0,CHOOSE(Inputs!$B$51,IF(I35>=Inputs!$B$54,Inputs!$B$52+Inputs!$B$53,Inputs!$B$52+Inputs!$B$53*(1.5*I35/Inputs!$B$54-0.5*(I35/Inputs!$B$54)^3)),Inputs!$B$52+Inputs!$B$53*(1-EXP(-3*I35/Inputs!$B$54)),Inputs!$B$52+Inputs!$B$53*(1-EXP(-3*(I35/Inputs!$B$54)^2)))) -> 0.10570313
A36: 3 | B36: =A36*Inputs!$B$55 -> 300 | C36: =COUNTIFS($B$102:$U$121,">="&(B36-Inputs!$B$55/2),$B$102:$U$121,"<"&(B36+Inputs!$B$55/2))/2 -> 45 | D36: =IFERROR(AVERAGEIFS($B$102:$U$121,$B$102:$U$121,">="&(B36-Inputs!$B$55/2),$B$102:$U$121,"<"&(B36+Inputs!$B$55/2)),0) -> 302.63706 | E36: =IFERROR(AVERAGEIFS($B$125:$U$144,$B$102:$U$121,">="&(B36-Inputs!$B$55/2),$B$102:$U$121,"<"&(B36+Inputs!$B$55/2)),0) -> 0.13787306 | F36: =IF(D36=0,0,CHOOSE(Inputs!$B$51,IF(D36>=Inputs!$B$54,Inputs!$B$52+Inputs!$B$53,Inputs!$B$52+Inputs!$B$53*(1.5*D36/Inputs!$B$54-0.5*(D36/Inputs!$B$54)^3)),Inputs!$B$52+Inputs!$B$53*(1-EXP(-3*D36/Inputs!$B$54)),Inputs!$B$52+Inputs!$B$53*(1-EXP(-3*(D36/Inputs!$B$54)^2)))) -> 0.15 | G36: =C36*(E36-F36)^2 -> 0.0066178252 | I36: 100 | J36: =IF(I36=0,0,CHOOSE(Inputs!$B$51,IF(I36>=Inputs!$B$54,Inputs!$B$52+Inputs!$B$53,Inputs!$B$52+Inputs!$B$53*(1.5*I36/Inputs!$B$54-0.5*(I36/Inputs!$B$54)^3)),Inputs!$B$52+Inputs!$B$53*(1-EXP(-3*I36/Inputs!$B$54)),Inputs!$B$52+Inputs!$B$53*(1-EXP(-3*(I36/Inputs!$B$54)^2)))) -> 0.128125
A37: 4 | B37: =A37*Inputs!$B$55 -> 400 | C37: =COUNTIFS($B$102:$U$121,">="&(B37-Inputs!$B$55/2),$B$102:$U$121,"<"&(B37+Inputs!$B$55/2))/2 -> 32 | D37: =IFERROR(AVERAGEIFS($B$102:$U$121,$B$102:$U$121,">="&(B37-Inputs!$B$55/2),$B$102:$U$121,"<"&(B37+Inputs!$B$55/2)),0) -> 393.98581 | E37: =IFERROR(AVERAGEIFS($B$125:$U$144,$B$102:$U$121,">="&(B37-Inputs!$B$55/2),$B$102:$U$121,"<"&(B37+Inputs!$B$55/2)),0) -> 0.12442227 | F37: =IF(D37=0,0,CHOOSE(Inputs!$B$51,IF(D37>=Inputs!$B$54,Inputs!$B$52+Inputs!$B$53,Inputs!$B$52+Inputs!$B$53*(1.5*D37/Inputs!$B$54-0.5*(D37/Inputs!$B$54)^3)),Inputs!$B$52+Inputs!$B$53*(1-EXP(-3*D37/Inputs!$B$54)),Inputs!$B$52+Inputs!$B$53*(1-EXP(-3*(D37/Inputs!$B$54)^2)))) -> 0.15 | G37: =C37*(E37-F37)^2 -> 0.020935056 | I37: 150 | J37: =IF(I37=0,0,CHOOSE(Inputs!$B$51,IF(I37>=Inputs!$B$54,Inputs!$B$52+Inputs!$B$53,Inputs!$B$52+Inputs!$B$53*(1.5*I37/Inputs!$B$54-0.5*(I37/Inputs!$B$54)^3)),Inputs!$B$52+Inputs!$B$53*(1-EXP(-3*I37/Inputs!$B$54)),Inputs!$B$52+Inputs!$B$53*(1-EXP(-3*(I37/Inputs!$B$54)^2)))) -> 0.14398437
A38: 5 | B38: =A38*Inputs!$B$55 -> 500 | C38: =COUNTIFS($B$102:$U$121,">="&(B38-Inputs!$B$55/2),$B$102:$U$121,"<"&(B38+Inputs!$B$55/2))/2 -> 2 | D38: =IFERROR(AVERAGEIFS($B$102:$U$121,$B$102:$U$121,">="&(B38-Inputs!$B$55/2),$B$102:$U$121,"<"&(B38+Inputs!$B$55/2)),0) -> 500 | E38: =IFERROR(AVERAGEIFS($B$125:$U$144,$B$102:$U$121,">="&(B38-Inputs!$B$55/2),$B$102:$U$121,"<"&(B38+Inputs!$B$55/2)),0) -> 0.0557 | F38: =IF(D38=0,0,CHOOSE(Inputs!$B$51,IF(D38>=Inputs!$B$54,Inputs!$B$52+Inputs!$B$53,Inputs!$B$52+Inputs!$B$53*(1.5*D38/Inputs!$B$54-0.5*(D38/Inputs!$B$54)^3)),Inputs!$B$52+Inputs!$B$53*(1-EXP(-3*D38/Inputs!$B$54)),Inputs!$B$52+Inputs!$B$53*(1-EXP(-3*(D38/Inputs!$B$54)^2)))) -> 0.15 | G38: =C38*(E38-F38)^2 -> 0.01778498 | I38: 200 | J38: =IF(I38=0,0,CHOOSE(Inputs!$B$51,IF(I38>=Inputs!$B$54,Inputs!$B$52+Inputs!$B$53,Inputs!$B$52+Inputs!$B$53*(1.5*I38/Inputs!$B$54-0.5*(I38/Inputs!$B$54)^3)),Inputs!$B$52+Inputs!$B$53*(1-EXP(-3*I38/Inputs!$B$54)),Inputs!$B$52+Inputs!$B$53*(1-EXP(-3*(I38/Inputs!$B$54)^2)))) -> 0.15
A39: Total | C39: =SUM(C34:C38) -> 190 | G39: =SUM(G34:G38) -> 0.051514729 | I39: 250 | J39: =IF(I39=0,0,CHOOSE(Inputs!$B$51,IF(I39>=Inputs!$B$54,Inputs!$B$52+Inputs!$B$53,Inputs!$B$52+Inputs!$B$53*(1.5*I39/Inputs!$B$54-0.5*(I39/Inputs!$B$54)^3)),Inputs!$B$52+Inputs!$B$53*(1-EXP(-3*I39/Inputs!$B$54)),Inputs!$B$52+Inputs!$B$53*(1-EXP(-3*(I39/Inputs!$B$54)^2)))) -> 0.15
A40: Variance of the values used | B40: =VAR(G6:G25) -> 0.13835526 | C40: m² | D40: Sample variance of coal thickness (or of the residuals when the trend is removed). | I40: 300 | J40: =IF(I40=0,0,CHOOSE(Inputs!$B$51,IF(I40>=Inputs!$B$54,Inputs!$B$52+Inputs!$B$53,Inputs!$B$52+Inputs!$B$53*(1.5*I40/Inputs!$B$54-0.5*(I40/Inputs!$B$54)^3)),Inputs!$B$52+Inputs!$B$53*(1-EXP(-3*I40/Inputs!$B$54)),Inputs!$B$52+Inputs!$B$53*(1-EXP(-3*(I40/Inputs!$B$54)^2)))) -> 0.15
A41: Total sill of the model (nugget + partial sill) | B41: =Inputs!$B$52+Inputs!$B$53 -> 0.15 | C41: m² | D41: A good fit has a total sill close to the variance above. | I41: 350 | J41: =IF(I41=0,0,CHOOSE(Inputs!$B$51,IF(I41>=Inputs!$B$54,Inputs!$B$52+Inputs!$B$53,Inputs!$B$52+Inputs!$B$53*(1.5*I41/Inputs!$B$54-0.5*(I41/Inputs!$B$54)^3)),Inputs!$B$52+Inputs!$B$53*(1-EXP(-3*I41/Inputs!$B$54)),Inputs!$B$52+Inputs!$B$53*(1-EXP(-3*(I41/Inputs!$B$54)^2)))) -> 0.15
A42: Weighted RMS error of the fit | B42: =SQRT(G39/C39) -> 0.01646603 | C42: m² | D42: Smaller is better. Adjust nugget, sill and range on Inputs until the model line follows the points. | I42: 400 | J42: =IF(I42=0,0,CHOOSE(Inputs!$B$51,IF(I42>=Inputs!$B$54,Inputs!$B$52+Inputs!$B$53,Inputs!$B$52+Inputs!$B$53*(1.5*I42/Inputs!$B$54-0.5*(I42/Inputs!$B$54)^3)),Inputs!$B$52+Inputs!$B$53*(1-EXP(-3*I42/Inputs!$B$54)),Inputs!$B$52+Inputs!$B$53*(1-EXP(-3*(I42/Inputs!$B$54)^2)))) -> 0.15
A43: Twenty boreholes give a rough experimental variogram: treat the fit as indicative and refit with real data. | I43: 450 | J43: =IF(I43=0,0,CHOOSE(Inputs!$B$51,IF(I43>=Inputs!$B$54,Inputs!$B$52+Inputs!$B$53,Inputs!$B$52+Inputs!$B$53*(1.5*I43/Inputs!$B$54-0.5*(I43/Inputs!$B$54)^3)),Inputs!$B$52+Inputs!$B$53*(1-EXP(-3*I43/Inputs!$B$54)),Inputs!$B$52+Inputs!$B$53*(1-EXP(-3*(I43/Inputs!$B$54)^2)))) -> 0.15
I44: 500 | J44: =IF(I44=0,0,CHOOSE(Inputs!$B$51,IF(I44>=Inputs!$B$54,Inputs!$B$52+Inputs!$B$53,Inputs!$B$52+Inputs!$B$53*(1.5*I44/Inputs!$B$54-0.5*(I44/Inputs!$B$54)^3)),Inputs!$B$52+Inputs!$B$53*(1-EXP(-3*I44/Inputs!$B$54)),Inputs!$B$52+Inputs!$B$53*(1-EXP(-3*(I44/Inputs!$B$54)^2)))) -> 0.15
I45: 550 | J45: =IF(I45=0,0,CHOOSE(Inputs!$B$51,IF(I45>=Inputs!$B$54,Inputs!$B$52+Inputs!$B$53,Inputs!$B$52+Inputs!$B$53*(1.5*I45/Inputs!$B$54-0.5*(I45/Inputs!$B$54)^3)),Inputs!$B$52+Inputs!$B$53*(1-EXP(-3*I45/Inputs!$B$54)),Inputs!$B$52+Inputs!$B$53*(1-EXP(-3*(I45/Inputs!$B$54)^2)))) -> 0.15
I46: 600 | J46: =IF(I46=0,0,CHOOSE(Inputs!$B$51,IF(I46>=Inputs!$B$54,Inputs!$B$52+Inputs!$B$53,Inputs!$B$52+Inputs!$B$53*(1.5*I46/Inputs!$B$54-0.5*(I46/Inputs!$B$54)^3)),Inputs!$B$52+Inputs!$B$53*(1-EXP(-3*I46/Inputs!$B$54)),Inputs!$B$52+Inputs!$B$53*(1-EXP(-3*(I46/Inputs!$B$54)^2)))) -> 0.15
A62: C. Ordinary kriging at the target point
A63: Item | B63: Value | C63: Unit | D63: What it means
A64: Target X | B64: =Inputs!$B$56 -> 200 | C64: m | D64: Set on Inputs. Choose a point that is not a borehole.
A65: Target Y | B65: =Inputs!$B$57 -> 200 | C65: m | D65: Set on Inputs.
...

Sheet Pit design
A1: Pit design — benches, overall slope, slope-wedge overburden and slope stability
A2: Bench geometry gives the overall pit slope. Each pit wall adds a wedge of overburden that no borehole shows. A planar-failure check tests whether the slope will stand.
A4: A. Pit walls and slope-wedge overburden, block by block
A5: Block | B5: Pit depth (m) | C5: Economic (1 = yes) | D5: Benches | E5: Overall slope (degrees) | F5: North wall | G5: South wall | H5: West wall | I5: East wall | J5: Wall length (m) | K5: Wall depth (m) | L5: Wedge volume (BCM)
A6: =Reserve!A6 -> A1 | B6: =Reserve!B6+Reserve!C6 -> 26.5 | C6: =IF(Reserve!I6="Yes",1,0) -> 1 | D6: =ROUNDUP(B6/Inputs!$B$59,0) -> 3 | E6: =DEGREES(ATAN(B6/(B6/TAN(RADIANS(Inputs!$B$60))+(D6-1)*Inputs!$B$61))) -> 45.939135 | F6: =IF($C6=1,IF(IFERROR(INDEX($C$6:$C$25,MATCH(CHAR(CODE(LEFT($A6,1))-1)&MID($A6,2,9),$A$6:$A$25,0)),0)=1,0,1),0) -> 1 | G6: =IF($C6=1,IF(IFERROR(INDEX($C$6:$C$25,MATCH(CHAR(CODE(LEFT($A6,1))+1)&MID($A6,2,9),$A$6:$A$25,0)),0)=1,0,1),0) -> 0 | H6: =IF($C6=1,IF(IFERROR(INDEX($C$6:$C$25,MATCH(LEFT($A6,1)&(VALUE(MID($A6,2,9))-1),$A$6:$A$25,0)),0)=1,0,1),0) -> 1 | I6: =IF($C6=1,IF(IFERROR(INDEX($C$6:$C$25,MATCH(LEFT($A6,1)&(VALUE(MID($A6,2,9))+1),$A$6:$A$25,0)),0)=1,0,1),0) -> 0 | J6: =(F6+G6)*Inputs!$B$6+(H6+I6)*Inputs!$B$7 -> 200 | K6: =IF(J6>0,B6,0) -> 26.5 | L6: =J6*0.5*B6^2/TAN(RADIANS(E6)) -> 67959.81
A7: =Reserve!A7 -> A2 | B7: =Reserve!B7+Reserve!C7 -> 31 | C7: =IF(Reserve!I7="Yes",1,0) -> 1 | D7: =ROUNDUP(B7/Inputs!$B$59,0) -> 4 | E7: =DEGREES(ATAN(B7/(B7/TAN(RADIANS(Inputs!$B$60))+(D7-1)*Inputs!$B$61))) -> 41.302804 | F7: =IF($C7=1,IF(IFERROR(INDEX($C$6:$C$25,MATCH(CHAR(CODE(LEFT($A7,1))-1)&MID($A7,2,9),$A$6:$A$25,0)),0)=1,0,1),0) -> 1 | G7: =IF($C7=1,IF(IFERROR(INDEX($C$6:$C$25,MATCH(CHAR(CODE(LEFT($A7,1))+1)&MID($A7,2,9),$A$6:$A$25,0)),0)=1,0,1),0) -> 0 | H7: =IF($C7=1,IF(IFERROR(INDEX($C$6:$C$25,MATCH(LEFT($A7,1)&(VALUE(MID($A7,2,9))-1),$A$6:$A$25,0)),0)=1,0,1),0) -> 0 | I7: =IF($C7=1,IF(IFERROR(INDEX($C$6:$C$25,MATCH(LEFT($A7,1)&(VALUE(MID($A7,2,9))+1),$A$6:$A$25,0)),0)=1,0,1),0) -> 0 | J7: =(F7+G7)*Inputs!$B$6+(H7+I7)*Inputs!$B$7 -> 100 | K7: =IF(J7>0,B7,0) -> 31 | L7: =J7*0.5*B7^2/TAN(RADIANS(E7)) -> 54688.77
A8: =Reserve!A8 -> A3 | B8: =Reserve!B8+Reserve!C8 -> 36.5 | C8: =IF(Reserve!I8="Yes",1,0) -> 1 | D8: =ROUNDUP(B8/Inputs!$B$59,0) -> 4 | E8: =DEGREES(ATAN(B8/(B8/TAN(RADIANS(Inputs!$B$60))+(D8-1)*Inputs!$B$61))) -> 44.390519 | F8: =IF($C8=1,IF(IFERROR(INDEX($C$6:$C$25,MATCH(CHAR(CODE(LEFT($A8,1))-1)&MID($A8,2,9),$A$6:$A$25,0)),0)=1,0,1),0) -> 1 | G8: =IF($C8=1,IF(IFERROR(INDEX($C$6:$C$25,MATCH(CHAR(CODE(LEFT($A8,1))+1)&MID($A8,2,9),$A$6:$A$25,0)),0)=1,0,1),0) -> 0 | H8: =IF($C8=1,IF(IFERROR(INDEX($C$6:$C$25,MATCH(LEFT($A8,1)&(VALUE(MID($A8,2,9))-1),$A$6:$A$25,0)),0)=1,0,1),0) -> 0 | I8: =IF($C8=1,IF(IFERROR(INDEX($C$6:$C$25,MATCH(LEFT($A8,1)&(VALUE(MID($A8,2,9))+1),$A$6:$A$25,0)),0)=1,0,1),0) -> 0 | J8: =(F8+G8)*Inputs!$B$6+(H8+I8)*Inputs!$B$7 -> 100 | K8: =IF(J8>0,B8,0) -> 36.5 | L8: =J8*0.5*B8^2/TAN(RADIANS(E8)) -> 68044.967
A9: =Reserve!A9 -> A4 | B9: =Reserve!B9+Reserve!C9 -> 43 | C9: =IF(Reserve!I9="Yes",1,0) -> 1 | D9: =ROUNDUP(B9/Inputs!$B$59,0) -> 5 | E9: =DEGREES(ATAN(B9/(B9/TAN(RADIANS(Inputs!$B$60))+(D9-1)*Inputs!$B$61))) -> 42.063088 | F9: =IF($C9=1,IF(IFERROR(INDEX($C$6:$C$25,MATCH(CHAR(CODE(LEFT($A9,1))-1)&MID($A9,2,9),$A$6:$A$25,0)),0)=1,0,1),0) -> 1 | G9: =IF($C9=1,IF(IFERROR(INDEX($C$6:$C$25,MATCH(CHAR(CODE(LEFT($A9,1))+1)&MID($A9,2,9),$A$6:$A$25,0)),0)=1,0,1),0) -> 0 | H9: =IF($C9=1,IF(IFERROR(INDEX($C$6:$C$25,MATCH(LEFT($A9,1)&(VALUE(MID($A9,2,9))-1),$A$6:$A$25,0)),0)=1,0,1),0) -> 0 | I9: =IF($C9=1,IF(IFERROR(INDEX($C$6:$C$25,MATCH(LEFT($A9,1)&(VALUE(MID($A9,2,9))+1),$A$6:$A$25,0)),0)=1,0,1),0) -> 1 | J9: =(F9+G9)*Inputs!$B$6+(H9+I9)*Inputs!$B$7 -> 200 | K9: =IF(J9>0,B9,0) -> 43 | L9: =J9*0.5*B9^2/TAN(RADIANS(E9)) -> 204898.1
A10: =Reserve!A10 -> A5 | B10: =Reserve!B10+Reserve!C10 -> 51.5 | C10: =IF(Reserve!I10="Yes",1,0) -> 0 | D10: =ROUNDUP(B10/Inputs!$B$59,0) -> 6 | E10: =DEGREES(ATAN(B10/(B10/TAN(RADIANS(Inputs!$B$60))+(D10-1)*Inputs!$B$61))) -> 41.240342 | F10: =IF($C10=1,IF(IFERROR(INDEX($C$6:$C$25,MATCH(CHAR(CODE(LEFT($A10,1))-1)&MID($A10,2,9),$A$6:$A$25,0)),0)=1,0,1),0) -> 0 | G10: =IF($C10=1,IF(IFERROR(INDEX($C$6:$C$25,MATCH(CHAR(CODE(LEFT($A10,1))+1)&MID($A10,2,9),$A$6:$A$25,0)),0)=1,0,1),0) -> 0 | H10: =IF($C10=1,IF(IFERROR(INDEX($C$6:$C$25,MATCH(LEFT($A10,1)&(VALUE(MID($A10,2,9))-1),$A$6:$A$25,0)),0)=1,0,1),0) -> 0 | I10: =IF($C10=1,IF(IFERROR(INDEX($C$6:$C$25,MATCH(LEFT($A10,1)&(VALUE(MID($A10,2,9))+1),$A$6:$A$25,0)),0)=1,0,1),0) -> 0 | J10: =(F10+G10)*Inputs!$B$6+(H10+I10)*Inputs!$B$7 -> 0 | K10: =IF(J10>0,B10,0) -> 0 | L10: =J10*0.5*B10^2/TAN(RADIANS(E10)) -> 0
A11: =Reserve!A11 -> B1 | B11: =Reserve!B11+Reserve!C11 -> 29 | C11: =IF(Reserve!I11="Yes",1,0) -> 1 | D11: =ROUNDUP(B11/Inputs!$B$59,0) -> 3 | E11: =DEGREES(ATAN(B11/(B11/TAN(RADIANS(Inputs!$B$60))+(D11-1)*Inputs!$B$61))) -> 47.519839 | F11: =IF($C11=1,IF(IFERROR(INDEX($C$6:$C$25,MATCH(CHAR(CODE(LEFT($A11,1))-1)&MID($A11,2,9),$A$6:$A$25,0)),0)=1,0,1),0) -> 0 | G11: =IF($C11=1,IF(IFERROR(INDEX($C$6:$C$25,MATCH(CHAR(CODE(LEFT($A11,1))+1)&MID($A11,2,9),$A$6:$A$25,0)),0)=1,0,1),0) -> 0 | H11: =IF($C11=1,IF(IFERROR(INDEX($C$6:$C$25,MATCH(LEFT($A11,1)&(VALUE(MID($A11,2,9))-1),$A$6:$A$25,0)),0)=1,0,1),0) -> 1 | I11: =IF($C11=1,IF(IFERROR(INDEX($C$6:$C$25,MATCH(LEFT($A11,1)&(VALUE(MID($A11,2,9))+1),$A$6:$A$25,0)),0)=1,0,1),0) -> 0 | J11: =(F11+G11)*Inputs!$B$6+(H11+I11)*Inputs!$B$7 -> 100 | K11: =IF(J11>0,B11,0) -> 29 | L11: =J11*0.5*B11^2/TAN(RADIANS(E11)) -> 38504.948
A12: =Reserve!A12 -> B2 | B12: =Reserve!B12+Reserve!C12 -> 33.5 | C12: =IF(Reserve!I12="Yes",1,0) -> 1 | D12: =ROUNDUP(B12/Inputs!$B$59,0) -> 4 | E12: =DEGREES(ATAN(B12/(B12/TAN(RADIANS(Inputs!$B$60))+(D12-1)*Inputs!$B$61))) -> 42.787138 | F12: =IF($C12=1,IF(IFERROR(INDEX($C$6:$C$25,MATCH(CHAR(CODE(LEFT($A12,1))-1)&MID($A12,2,9),$A$6:$A$25,0)),0)=1,0,1),0) -> 0 | G12: =IF($C12=1,IF(IFERROR(INDEX($C$6:$C$25,MATCH(CHAR(CODE(LEFT($A12,1))+1)&MID($A12,2,9),$A$6:$A$25,0)),0)=1,0,1),0) -> 0 | H12: =IF($C12=1,IF(IFERROR(INDEX($C$6:$C$25,MATCH(LEFT($A12,1)&(VALUE(MID($A12,2,9))-1),$A$6:$A$25,0)),0)=1,0,1),0) -> 0 | I12: =IF($C12=1,IF(IFERROR(INDEX($C$6:$C$25,MATCH(LEFT($A12,1)&(VALUE(MID($A12,2,9))+1),$A$6:$A$25,0)),0)=1,0,1),0) -> 0 | J12: =(F12+G12)*Inputs!$B$6+(H12+I12)*Inputs!$B$7 -> 0 | K12: =IF(J12>0,B12,0) -> 0 | L12: =J12*0.5*B12^2/TAN(RADIANS(E12)) -> 0
A13: =Reserve!A13 -> B3 | B13: =Reserve!B13+Reserve!C13 -> 39 | C13: =IF(Reserve!I13="Yes",1,0) -> 1 | D13: =ROUNDUP(B13/Inputs!$B$59,0) -> 4 | E13: =DEGREES(ATAN(B13/(B13/TAN(RADIANS(Inputs!$B$60))+(D13-1)*Inputs!$B$61))) -> 45.597587 | F13: =IF($C13=1,IF(IFERROR(INDEX($C$6:$C$25,MATCH(CHAR(CODE(LEFT($A13,1))-1)&MID($A13,2,9),$A$6:$A$25,0)),0)=1,0,1),0) -> 0 | G13: =IF($C13=1,IF(IFERROR(INDEX($C$6:$C$25,MATCH(CHAR(CODE(LEFT($A13,1))+1)&MID($A13,2,9),$A$6:$A$25,0)),0)=1,0,1),0) -> 0 | H13: =IF($C13=1,IF(IFERROR(INDEX($C$6:$C$25,MATCH(LEFT($A13,1)&(VALUE(MID($A13,2,9))-1),$A$6:$A$25,0)),0)=1,0,1),0) -> 0 | I13: =IF($C13=1,IF(IFERROR(INDEX($C$6:$C$25,MATCH(LEFT($A13,1)&(VALUE(MID($A13,2,9))+1),$A$6:$A$25,0)),0)=1,0,1),0) -> 0 | J13: =(F13+G13)*Inputs!$B$6+(H13+I13)*Inputs!$B$7 -> 0 | K13: =IF(J13>0,B13,0) -> 0 | L13: =J13*0.5*B13^2/TAN(RADIANS(E13)) -> 0
A14: =Reserve!A14 -> B4 | B14: =Reserve!B14+Reserve!C14 -> 45.5 | C14: =IF(Reserve!I14="Yes",1,0) -> 1 | D14: =ROUNDUP(B14/Inputs!$B$59,0) -> 5 | E14: =DEGREES(ATAN(B14/(B14/TAN(RADIANS(Inputs!$B$60))+(D14-1)*Inputs!$B$61))) -> 43.136306 | F14: =IF($C14=1,IF(IFERROR(INDEX($C$6:$C$25,MATCH(CHAR(CODE(LEFT($A14,1))-1)&MID($A14,2,9),$A$6:$A$25,0)),0)=1,0,1),0) -> 0 | G14: =IF($C14=1,IF(IFERROR(INDEX($C$6:$C$25,MATCH(CHAR(CODE(LEFT($A14,1))+1)&MID($A14,2,9),$A$6:$A$25,0)),0)=1,0,1),0) -> 0 | H14: =IF($C14=1,IF(IFERROR(INDEX($C$6:$C$25,MATCH(LEFT($A14,1)&(VALUE(MID($A14,2,9))-1),$A$6:$A$25,0)),0)=1,0,1),0) -> 0 | I14: =IF($C14=1,IF(IFERROR(INDEX($C$6:$C$25,MATCH(LEFT($A14,1)&(VALUE(MID($A14,2,9))+1),$A$6:$A$25,0)),0)=1,0,1),0) -> 1 | J14: =(F14+G14)*Inputs!$B$6+(H14+I14)*Inputs!$B$7 -> 100 | K14: =IF(J14>0,B14,0) -> 45.5 | L14: =J14*0.5*B14^2/TAN(RADIANS(E14)) -> 110475.47
A15: =Reserve!A15 -> B5 | B15: =Reserve!B15+Reserve!C15 -> 53.5 | C15: =IF(Reserve!I15="Yes",1,0) -> 0 | D15: =ROUNDUP(B15/Inputs!$B$59,0) -> 6 | E15: =DEGREES(ATAN(B15/(B15/TAN(RADIANS(Inputs!$B$60))+(D15-1)*Inputs!$B$61))) -> 41.973814 | F15: =IF($C15=1,IF(IFERROR(INDEX($C$6:$C$25,MATCH(CHAR(CODE(LEFT($A15,1))-1)&MID($A15,2,9),$A$6:$A$25,0)),0)=1,0,1),0) -> 0 | G15: =IF($C15=1,IF(IFERROR(INDEX($C$6:$C$25,MATCH(CHAR(CODE(LEFT($A15,1))+1)&MID($A15,2,9),$A$6:$A$25,0)),0)=1,0,1),0) -> 0 | H15: =IF($C15=1,IF(IFERROR(INDEX($C$6:$C$25,MATCH(LEFT($A15,1)&(VALUE(MID($A15,2,9))-1),$A$6:$A$25,0)),0)=1,0,1),0) -> 0 | I15: =IF($C15=1,IF(IFERROR(INDEX($C$6:$C$25,MATCH(LEFT($A15,1)&(VALUE(MID($A15,2,9))+1),$A$6:$A$25,0)),0)=1,0,1),0) -> 0 | J15: =(F15+G15)*Inputs!$B$6+(H15+I15)*Inputs!$B$7 -> 0 | K15: =IF(J15>0,B15,0) -> 0 | L15: =J15*0.5*B15^2/TAN(RADIANS(E15)) -> 0
A16: =Reserve!A16 -> C1 | B16: =Reserve!B16+Reserve!C16 -> 28.5 | C16: =IF(Reserve!I16="Yes",1,0) -> 1 | D16: =ROUNDUP(B16/Inputs!$B$59,0) -> 3 | E16: =DEGREES(ATAN(B16/(B16/TAN(RADIANS(Inputs!$B$60))+(D16-1)*Inputs!$B$61))) -> 47.219637 | F16: =IF($C16=1,IF(IFERROR(INDEX($C$6:$C$25,MATCH(CHAR(CODE(LEFT($A16,1))-1)&MID($A16,2,9),$A$6:$A$25,0)),0)=1,0,1),0) -> 0 | G16: =IF($C16=1,IF(IFERROR(INDEX($C$6:$C$25,MATCH(CHAR(CODE(LEFT($A16,1))+1)&MID($A16,2,9),$A$6:$A$25,0)),0)=1,0,1),0) -> 0 | H16: =IF($C16=1,IF(IFERROR(INDEX($C$6:$C$25,MATCH(LEFT($A16,1)&(VALUE(MID($A16,2,9))-1),$A$6:$A$25,0)),0)=1,0,1),0) -> 1 | I16: =IF($C16=1,IF(IFERROR(INDEX($C$6:$C$25,MATCH(LEFT($A16,1)&(VALUE(MID($A16,2,9))+1),$A$6:$A$25,0)),0)=1,0,1),0) -> 0 | J16: =(F16+G16)*Inputs!$B$6+(H16+I16)*Inputs!$B$7 -> 100 | K16: =IF(J16>0,B16,0) -> 28.5 | L16: =J16*0.5*B16^2/TAN(RADIANS(E16)) -> 37581.741
A17: =Reserve!A17 -> C2 | B17: =Reserve!B17+Reserve!C17 -> 33 | C17: =IF(Reserve!I17="Yes",1,0) -> 1 | D17: =ROUNDUP(B17/Inputs!$B$59,0) -> 4 | E17: =DEGREES(ATAN(B17/(B17/TAN(RADIANS(Inputs!$B$60))+(D17-1)*Inputs!$B$61))) -> 42.501714 | F17: =IF($C17=1,IF(IFERROR(INDEX($C$6:$C$25,MATCH(CHAR(CODE(LEFT($A17,1))-1)&MID($A17,2,9),$A$6:$A$25,0)),0)=1,0,1),0) -> 0 | G17: =IF($C17=1,IF(IFERROR(INDEX($C$6:$C$25,MATCH(CHAR(CODE(LEFT($A17,1))+1)&MID($A17,2,9),$A$6:$A$25,0)),0)=1,0,1),0) -> 0 | H17: =IF($C17=1,IF(IFERROR(INDEX($C$6:$C$25,MATCH(LEFT($A17,1)&(VALUE(MID($A17,2,9))-1),$A$6:$A$25,0)),0)=1,0,1),0) -> 0 | I17: =IF($C17=1,IF(IFERROR(INDEX($C$6:$C$25,MATCH(LEFT($A17,1)&(VALUE(MID($A17,2,9))+1),$A$6:$A$25,0)),0)=1,0,1),0) -> 0 | J17: =(F17+G17)*Inputs!$B$6+(H17+I17)*Inputs!$B$7 -> 0 | K17: =IF(J17>0,B17,0) -> 0 | L17: =J17*0.5*B17^2/TAN(RADIANS(E17)) -> 0
... A25: =Reserve!A25 -> D5 | B25: =Reserve!B25+Reserve!C25 -> 49 | C25: =IF(Reserve!I25="Yes",1,0) -> 0 | D25: =ROUNDUP(B25/Inputs!$B$59,0) -> 5 | E25: =DEGREES(ATAN(B25/(B25/TAN(RADIANS(Inputs!$B$60))+(D25-1)*Inputs!$B$61))) -> 44.516216 | F25: =IF($C25=1,IF(IFERROR(INDEX($C$6:$C$25,MATCH(CHAR(CODE(LEFT($A25,1))-1)&MID($A25,2,9),$A$6:$A$25,0)),0)=1,0,1),0) -> 0 | G25: =IF($C25=1,IF(IFERROR(INDEX($C$6:$C$25,MATCH(CHAR(CODE(LEFT($A25,1))+1)&MID($A25,2,9),$A$6:$A$25,0)),0)=1,0,1),0) -> 0 | H25: =IF($C25=1,IF(IFERROR(INDEX($C$6:$C$25,MATCH(LEFT($A25,1)&(VALUE(MID($A25,2,9))-1),$A$6:$A$25,0)),0)=1,0,1),0) -> 0 | I25: =IF($C25=1,IF(IFERROR(INDEX($C$6:$C$25,MATCH(LEFT($A25,1)&(VALUE(MID($A25,2,9))+1),$A$6:$A$25,0)),0)=1,0,1),0) -> 0 | J25: =(F25+G25)*Inputs!$B$6+(H25+I25)*Inputs!$B$7 -> 0 | K25: =IF(J25>0,B25,0) -> 0 | L25: =J25*0.5*B25^2/TAN(RADIANS(E25)) -> 0
A26: Total / deepest wall | C26: =SUM(C6:C25) -> 16 | J26: =SUM(J6:J25) -> 1600 | K26: =MAX(K6:K25) -> 45.5 | L26: =SUM(L6:L25) -> 1076129
A27: A wall exists where an economic block meets the grid edge or a block left unmined (flag 1). Corner wedges are ignored. Overall slope: tan β = D ÷ (D ÷ tan α + (N − 1) × berm).
A29: B. Effect on the stripping ratio
A30: Item | B30: Value | C30: Unit | D30: What it means
A31: Overburden in economic blocks | B31: =Reserve!B37 -> 4320000 | C31: BCM | D31: Block-by-block overburden from the Reserve sheet.
A32: Slope-wedge overburden | B32: =L26 -> 1076129 | C32: BCM | D32: Extra rock to cut back the pit walls: ½ × D² × cot β per metre of wall.
A33: Wedge switch (Inputs) | B33: =Inputs!$B$46 -> 1 | C33: 1 or 0 | D33: 1 includes the wedge in the stripping ratio used by Fleet, Economics and Cash flow.
A34: Overburden to remove, including wedge | B34: =B31+B33*B32 -> 5396129 | C34: BCM
A35: Coal in place, economic blocks | B35: =Reserve!B36 -> 1841000 | C35: t
A36: Stripping ratio, blocks only | B36: =IFERROR(B31/B35,0) -> 2.3465508 | C36: m³/t | D36: What the simple block model gives.
A37: Stripping ratio including pit slopes | B37: =IFERROR(B34/B35,0) -> 2.9310858 | C37: m³/t | D37: Feeds the Reserve sheet (stripping ratio, economic blocks).
A38: Increase due to pit slopes | B38: =IFERROR(B37/B36-1,0) -> 0.24910393 | C38: %
A40: C. Planar-failure factor of safety, deepest wall (dry slope, no tension crack)
A41: Item | B41: Value | C41: Unit | D41: What it means
A42: Slope height, H (deepest wall) | B42: =K26 -> 45.5 | C42: m | D42: Deepest wall on the economic pit outline.
A43: Overall slope angle of that wall, ψf | B43: =IFERROR(INDEX(E6:E25,MATCH(K26,K6:K25,0)),0) -> 43.136306 | C43: degrees | D43: From the bench geometry for that wall.
A44: Unit weight of rock, γ | B44: =Inputs!$B$9*9.81 -> 21.582 | C44: kN/m³ | D44: Overburden density (t/m³) × 9.81.
A45: Cohesion, c | B45: =Inputs!$B$62 -> 30 | C45: kPa
A46: Friction angle, φ | B46: =Inputs!$B$63 -> 30 | C46: degrees
A47: Failure plane dip, ψp | B47: =Inputs!$B$64 -> 35 | C47: degrees | D47: The plane must be flatter than the slope to daylight in the face.
A48: Weight of sliding block, W | B48: =IF(AND(B42>0,B47<B43),0.5*B44*B42^2*(1/TAN(RADIANS(B47))-1/TAN(RADIANS(B43))),0) -> 8062.1075 | C48: kN per m | D48: W = ½ γ H² (cot ψp − cot ψf), per metre of wall length.
A49: Area of failure plane, A | B49: =IF(B42>0,B42/SIN(RADIANS(B47)),0) -> 79.326829 | C49: m² per m | D49: A = H ÷ sin ψp.
A50: Resisting force | B50: =B45*B49+B48*COS(RADIANS(B47))*TAN(RADIANS(B46)) -> 6192.6791 | C50: kN per m | D50: c × A + W cos ψp tan φ.
...

Sheet Fleet
A1: Fleet — how many excavators and dumpers does the target need?
A2: Column B = overburden, column C = coal. Every row is a formula; the note says what it means.
A4: Item | B4: Overburden | C4: Coal | D4: Unit | E4: What it means
A5: A. Excavator productivity
A6: Swell factor (loose ÷ bank) | B6: =Inputs!$B$15 -> 1.35 | C6: =Inputs!$B$16 -> 1.3 | D6: ratio | E6: Pulled from Inputs.
A7: Density in the bank | B7: =Inputs!$B$9 -> 2.2 | C7: =Inputs!$B$8 -> 1.4 | D7: t/m³ | E7: Pulled from Inputs.
A8: Bucket payload per pass | B8: =Inputs!$B$13*Inputs!$B$14/B6 -> 2.5185185 | C8: =Inputs!$B$13*Inputs!$B$14/C6 -> 2.6153846 | D8: BCM | E8: Bucket × fill factor ÷ swell. The loose rock in the bucket, converted back to bank volume.
A9: Bucket payload per pass | B9: =B8*B7 -> 5.5407407 | C9: =C8*C7 -> 3.6615385 | D9: t | E9: Bank volume × density.
A10: Excavator passes per hour | B10: =3600/Inputs!$B$17*Inputs!$B$18/60 -> 100 | C10: =3600/Inputs!$B$17*Inputs!$B$18/60 -> 100 | D10: passes | E10: 3600 s ÷ cycle time gives passes in a full hour; × efficiency (min ÷ 60) gives productive passes.
A11: Excavator productivity | B11: =B8*B10 -> 251.85185 | C11: =C8*C10 -> 261.53846 | D11: BCM/hr | E11: Payload per pass × passes per hour.
A12: Excavator productivity | B12: =B11*B7 -> 554.07407 | C12: =C11*C7 -> 366.15385 | D12: t/hr | E12: BCM/hr × density.
A13: B. Dumper cycle (one trip)
A14: Haul distance one way | B14: =Inputs!$B$21 -> 2 | C14: =Inputs!$B$22 -> 3 | D14: km | E14: Pulled from Inputs.
A15: Buckets needed to load one dumper | B15: =ROUNDDOWN(Inputs!$B$20/B9,0) -> 6 | C15: =ROUNDDOWN(Inputs!$B$20/C9,0) -> 9 | D15: passes | E15: Rated payload ÷ tonnes per bucket, rounded DOWN so the dumper is not overloaded.
A16: Actual payload per trip | B16: =B15*B9 -> 33.244444 | C16: =C15*C9 -> 32.953846 | D16: t | E16: Whole buckets × tonnes per bucket.
A17: Loading time | B17: =B15*Inputs!$B$17/60 -> 3 | C17: =C15*Inputs!$B$17/60 -> 4.5 | D17: min | E17: Buckets × excavator cycle time.
A18: Loaded haul time | B18: =B14/Inputs!$B$23*60 -> 6 | C18: =C14/Inputs!$B$23*60 -> 9 | D18: min | E18: Distance ÷ speed × 60.
A19: Return time, empty | B19: =B14/Inputs!$B$24*60 -> 4.2857143 | C19: =C14/Inputs!$B$24*60 -> 6.4285714 | D19: min | E19: Distance ÷ speed × 60.
A20: Spotting + dumping time | B20: =Inputs!$B$25+Inputs!$B$26 -> 2 | C20: =Inputs!$B$25+Inputs!$B$26 -> 2 | D20: min | E20: Fixed time at each end.
A21: Total dumper cycle time | B21: =B17+B18+B19+B20 -> 15.285714 | C21: =C17+C18+C19+C20 -> 21.928571 | D21: min | E21: Load + haul + return + spot and dump.
A22: Trips per hour | B22: =Inputs!$B$27/B21 -> 3.271028 | C22: =Inputs!$B$27/C21 -> 2.2801303 | D22: trips | E22: Productive minutes per hour ÷ cycle time.
A23: Dumper productivity | B23: =B22*B16 -> 108.74351 | C23: =C22*C16 -> 75.139063 | D23: t/hr | E23: Trips per hour × payload per trip.
A24: Dumpers needed to keep one excavator busy | B24: =B21/B17 -> 5.0952381 | C24: =C21/C17 -> 4.8730159 | D24: dumpers | E24: Cycle time ÷ loading time. This is the fleet match number.
A25: C. Fleet required for the production target
A26: Effective hours per machine per year | B26: =Inputs!$B$29*Inputs!$B$30*Inputs!$B$31*Inputs!$B$32*Inputs!$B$33 -> 5385.6 | D26: hours | E26: Days × shifts × hours × availability × utilisation.
A27: Quantity to move per year | B27: =Inputs!$B$11*Reserve!$B$38 -> 1465542.9 | C27: =Inputs!$B$11/Inputs!$B$8 -> 357142.86 | D27: BCM/yr | E27: Overburden = production × stripping ratio (economic blocks). Coal = production ÷ density.
A28: Quantity to move per year | B28: =B27*B7 -> 3224194.4 | C28: =Inputs!$B$11 -> 500000 | D28: t/yr | E28: Overburden BCM × density. Coal = production target.
A29: Excavator hours needed per year | B29: =B28/B12 -> 5819.0674 | C29: =C28/C12 -> 1365.5462 | D29: hours | E29: Tonnes to move ÷ excavator tonnes per hour.
A30: Dumper hours needed per year | B30: =B28/B23 -> 29649.534 | C30: =C28/C23 -> 6654.3284 | D30: hours | E30: Tonnes to move ÷ dumper tonnes per hour.
A31: Excavators required (overburden + coal) | B31: =ROUNDUP((B29+C29)/B26,0) -> 2 | D31: machines | E31: Total hours needed ÷ hours one machine can work, rounded UP.
A32: Dumpers required (overburden + coal) | B32: =ROUNDUP((B30+C30)/B26,0) -> 7 | D32: machines | E32: Same method for dumpers.
A33: Excavator fleet utilisation | B33: =(B29+C29)/(B31*B26) -> 0.66702072 | D33: % | E33: How busy the rounded-up fleet is. Very low means you may be over-sized.
A34: Dumper fleet utilisation | B34: =(B30+C30)/(B32*B26) -> 0.9629876 | D34: % | E34: Same check for dumpers.
A35: Dumpers per excavator in the fleet | B35: =B32/B31 -> 3.5 | D35: ratio | E35: Compare with the match number above.

Sheet Safety
A1: Safety — blast vibration against DGMS limits, and haul-ramp stopping distance
A2: Ground vibration from the scaled-distance law, and how far a loaded dumper travels before it stops on the ramp. Sample site constants: replace with monitoring data.
A4: A. Blast design
A5: Item | B5: Value | C5: Unit | D5: What it means
A6: Burden, B | B6: =Inputs!$B$92 -> 4 | C6: m
A7: Spacing, S | B7: =Inputs!$B$93 -> 5 | C7: m
A8: Bench height, H | B8: =Inputs!$B$59 -> 10 | C8: m | D8: From the Pit design inputs.
A9: Powder factor | B9: =Inputs!$B$90 -> 0.35 | C9: kg/m³
A10: Rock broken per hole | B10: =B6*B7*B8 -> 200 | C10: BCM | D10: Burden × spacing × height (sub-drilling ignored).
A11: Explosive charge per hole, Q | B11: =B9*B10 -> 70 | C11: kg
A12: Holes firing per delay | B12: =Inputs!$B$94 -> 2 | C12: holes
A13: Maximum charge per delay, Qd | B13: =B11*B12 -> 140 | C13: kg | D13: Controls the ground vibration.
A14: Explosive cost | B14: =Inputs!$B$90*Inputs!$B$91 -> 19.25 | C14: ₹/BCM | D14: Powder factor × cost per kg.
A15: Drilling and blasting cost in the model | B15: =Inputs!$B$35 -> 35 | C15: ₹/BCM | D15: Inputs section 5.
A16: Explosive share of the drilling and blasting cost | B16: =IFERROR(B14/B15,0) -> 0.55 | C16: % | D16: Typically about half. The rest is drilling, accessories and labour.
A18: B. Ground vibration: peak particle velocity (PPV) = K × (R ÷ √Qd)^−β
A19: Item | B19: Value | C19: Unit | D19: What it means
A20: Distance to nearest structure, R | B20: =Inputs!$B$95 -> 300 | C20: m
A21: Site constant K | B21: =Inputs!$B$96 -> 500 | C21: mm/s
A22: Site constant β | B22: =Inputs!$B$97 -> 1.6
A23: Scaled distance, R ÷ √Qd | B23: =B20/SQRT(B13) -> 25.354628 | C23: m/kg^0.5
A24: Predicted PPV | B24: =B21*B23^(-B22) -> 2.8345128 | C24: mm/s
A25: Permissible PPV (DGMS table) | B25: =INDEX($B$34:$D$38,Inputs!$B$98,Inputs!$B$99) -> 10 | C25: mm/s | D25: Looked up from the structure category and frequency band chosen on Inputs.
A26: Status | B26: =IF(B24<=B25,"Within limit","EXCEEDS limit") -> Within limit
A27: Margin: permissible ÷ predicted | B27: =IFERROR(B25/B24,0) -> 3.5279431 | C27: ratio | D27: Above 1 is safe. Aim for a comfortable margin because site constants are uncertain.
A28: Safe distance at this charge | B28: =SQRT(B13)*(B21/B25)^(1/B22) -> 136.43326 | C28: m | D28: Closest a structure can be for the PPV to equal the limit.
A29: Maximum charge per delay at this distance | B29: =(B20/(B21/B25)^(1/B22))^2 -> 676.90856 | C29: kg | D29: Largest Qd that keeps the PPV at the limit. Reduce holes per delay if the status fails.
A31: Permissible PPV by structure and dominant frequency (mm/s)
A32: DGMS (Tech)(S&T) Circular No. 7 of 1997, permissible peak particle velocity at the foundation of structures in mining areas. Verify against the latest circular.
A33: Structure category | B33: Below 8 Hz | C33: 8 to 25 Hz | D33: Above 25 Hz
A34: 1 Domestic houses, not owned by the mine | B34: 5 | C34: 10 | D34: 15
A35: 2 Industrial buildings (RCC and framed), not owned by the mine | B35: 10 | C35: 20 | D35: 25
A36: 3 Historical and sensitive structures | B36: 2 | C36: 5 | D36: 10
A37: 4 Domestic houses, owned by the mine (limited life) | B37: 10 | C37: 15 | D37: 25
A38: 5 Industrial buildings, owned by the mine (limited life) | B38: 15 | C38: 25 | D38: 50
A40: C. Stopping distance for a loaded dumper going down the ramp
A41: Speed (km/h) | B41: Speed (m/s) | C41: Reaction distance (m) | D41: Braking distance (m) | E41: Stopping distance (m) | F41: Within sight distance?
A42: =Inputs!$B$23 -> 20 | B42: =A42/3.6 -> 5.5555556 | C42: =B42*Inputs!$B$100 -> 8.3333333 | D42: =IF(Inputs!$B$101>Inputs!$B$66/100,B42^2/(2*9.81*(Inputs!$B$101-Inputs!$B$66/100)),"cannot stop") -> 5.8262917 | E42: =IF(ISNUMBER(D42),C42+D42,"cannot stop") -> 14.159625 | F42: =IF(ISNUMBER(E42),IF(E42<=Inputs!$B$102,"Yes","No"),"No") -> Yes
A43: =Inputs!$B$103 -> 30 | B43: =A43/3.6 -> 8.3333333 | C43: =B43*Inputs!$B$100 -> 12.5 | D43: =IF(Inputs!$B$101>Inputs!$B$66/100,B43^2/(2*9.81*(Inputs!$B$101-Inputs!$B$66/100)),"cannot stop") -> 13.109156 | E43: =IF(ISNUMBER(D43),C43+D43,"cannot stop") -> 25.609156 | F43: =IF(ISNUMBER(E43),IF(E43<=Inputs!$B$102,"Yes","No"),"No") -> Yes
A44: 10 | B44: =A44/3.6 -> 2.7777778 | C44: =B44*Inputs!$B$100 -> 4.1666667 | D44: =IF(Inputs!$B$101>Inputs!$B$66/100,B44^2/(2*9.81*(Inputs!$B$101-Inputs!$B$66/100)),"cannot stop") -> 1.4565729 | E44: =IF(ISNUMBER(D44),C44+D44,"cannot stop") -> 5.6232396 | F44: =IF(ISNUMBER(E44),IF(E44<=Inputs!$B$102,"Yes","No"),"No") -> Yes
...

Sheet Quality and royalty
A1: Quality and royalty — washability, washing economics and statutory levies
A2: Float-and-sink data give the yield at a target ash. Royalty, DMF and NMET replace the flat levy placeholder. SAMPLE DATA: replace the yellow cells with your own float-sink test.
A4: A. Float-and-sink (washability) data for the run-of-mine coal
A5: Density fraction | B5: Upper density (SG) | C5: Weight (%) | D5: Ash (%) | E5: Cumulative float yield (%) | F5: Cumulative float ash (%) | G5: Ash contribution (% of total)
A6: Float 1.3 | B6: 1.3 | C6: 6 | D6: 8 | E6: =SUM($C$6:C6) -> 6 | F6: =SUM($G$6:G6)/E6*100 -> 8 | G6: =C6*D6/100 -> 0.48
A7: 1.3 – 1.4 | B7: 1.4 | C7: 12 | D7: 14 | E7: =SUM($C$6:C7) -> 18 | F7: =SUM($G$6:G7)/E7*100 -> 12 | G7: =C7*D7/100 -> 1.68
A8: 1.4 – 1.5 | B8: 1.5 | C8: 14 | D8: 22 | E8: =SUM($C$6:C8) -> 32 | F8: =SUM($G$6:G8)/E8*100 -> 16.375 | G8: =C8*D8/100 -> 3.08
A9: 1.5 – 1.6 | B9: 1.6 | C9: 13 | D9: 32 | E9: =SUM($C$6:C9) -> 45 | F9: =SUM($G$6:G9)/E9*100 -> 20.888889 | G9: =C9*D9/100 -> 4.16
A10: 1.6 – 1.8 | B10: 1.8 | C10: 15 | D10: 44 | E10: =SUM($C$6:C10) -> 60 | F10: =SUM($G$6:G10)/E10*100 -> 26.666667 | G10: =C10*D10/100 -> 6.6
A11: 1.8 – 2.0 | B11: 2 | C11: 12 | D11: 58 | E11: =SUM($C$6:C11) -> 72 | F11: =SUM($G$6:G11)/E11*100 -> 31.888889 | G11: =C11*D11/100 -> 6.96
A12: Sink 2.0 | B12: — | C12: 28 | D12: 78 | E12: =SUM($C$6:C12) -> 100 | F12: =SUM($G$6:G12)/E12*100 -> 44.8 | G12: =C12*D12/100 -> 21.84
A13: Total | C13: =SUM(C6:C12) -> 100 | F13: =F12 -> 44.8 | G13: =SUM(G6:G12) -> 44.8
A14: Weights must total 100 %. Cumulative float ash = Σ(weight × ash) ÷ cumulative yield. The last row's cumulative ash is the run-of-mine ash.
A16: B. Washing result at the target ash
A17: Item | B17: Value | C17: Unit | D17: What it means
A18: Target clean-coal ash | B18: =Inputs!$B$71 -> 28 | C18: % | D18: Set on Inputs.
A19: Run-of-mine (raw) ash | B19: =F12 -> 44.8 | C19: %
A20: Position on the washability curve | B20: =IFERROR(MATCH(B18,$F$6:$F$12,1),0) -> 5 | C20: index | D20: Last float-sink row whose cumulative ash is at or below the target.
A21: Interpolation fraction | B21: =IF(AND(B20>=1,B20<=6),(B18-INDEX($F$6:$F$12,B20))/(INDEX($F$6:$F$12,B20+1)-INDEX($F$6:$F$12,B20)),0) -> 0.25531915 | D21: Position between two points of the cumulative curve.
A22: Theoretical yield at the target ash | B22: =IF(B20=0,0,IF(B20>=7,100,INDEX($E$6:$E$12,B20)+B21*(INDEX($E$6:$E$12,B20+1)-INDEX($E$6:$E$12,B20)))) -> 63.06383 | C22: % | D22: Yield of a perfect separation, read off the washability curve.
A23: Cut-point density | B23: =IF(AND(B20>=1,B20<=5),INDEX($B$6:$B$12,B20)+B21*(INDEX($B$6:$B$12,B20+1)-INDEX($B$6:$B$12,B20)),"n/a") -> 1.8510638 | C23: SG | D23: Density at which the washery separates clean coal from reject.
A24: Near-gravity material, cut-point ± 0.1 SG | B24: =IFERROR((INDEX($E$6:$E$11,MATCH((B23+0.1),$B$6:$B$11,1))+((B23+0.1)-INDEX($B$6:$B$11,MATCH((B23+0.1),$B$6:$B$11,1)))/(INDEX($B$6:$B$11,MATCH((B23+0.1),$B$6:$B$11,1)+1)-INDEX($B$6:$B$11,MATCH((B23+0.1),$B$6:$B$11,1)))*(INDEX($E$6:$E$11,MATCH((B23+0.1),$B$6:$B$11,1)+1)-INDEX($E$6:$E$11,MATCH((B23+0.1),$B$6:$B$11,1))))-(INDEX($E$6:$E$11,MATCH((B23-0.1),$B$6:$B$11,1))+((B23-0.1)-INDEX($B$6:$B$11,MATCH((B23-0.1),$B$6:$B$11,1)))/(INDEX($B$6:$B$11,MATCH((B23-0.1),$B$6:$B$11,1)+1)-INDEX($B$6:$B$11,MATCH((B23-0.1),$B$6:$B$11,1)))*(INDEX($E$6:$E$11,MATCH((B23-0.1),$B$6:$B$11,1)+1)-INDEX($E$6:$E$11,MATCH((B23-0.1),$B$6:$B$11,1)))),"n/a") -> 12.734043 | C24: % | D24: Material close to the cut density. More of it means harder separation and lower efficiency.
A25: Organic efficiency | B25: =Inputs!$B$72 -> 0.94 | C25: fraction | D25: Actual yield ÷ theoretical yield at the same ash.
A26: Actual yield at the target ash | B26: =B25*B22 -> 59.28 | C26: %
A27: Reject ash | B27: =IF(B26<100,(B19-B26/100*B18)/(1-B26/100),0) -> 69.257367 | C27: % | D27: Mass balance on ash: feed = clean + reject.
A29: C. Revenue per tonne of run-of-mine coal: wash or sell raw?
A30: Item | B30: Value | C30: Unit | D30: What it means
A31: Raw coal price | B31: =Inputs!$B$42 -> 2200 | C31: ₹/t | D31: Selling price in Inputs section 5.
A32: Washed coal price | B32: =Inputs!$B$73 -> 4200 | C32: ₹/t
A33: Washed yield (fraction of feed) | B33: =B26/100 -> 0.5928
A34: Revenue from washed coal, per tonne of feed | B34: =B33*B32 -> 2489.76 | C34: ₹/t | D34: Yield × washed price.
A35: Value of rejects, per tonne of feed | B35: =(1-B33)*Inputs!$B$75 -> 0 | C35: ₹/t
A36: Less: washing cost | B36: =Inputs!$B$74 -> 150 | C36: ₹/t
A37: Net realisation per tonne of ROM coal | B37: =B34+B35-B36 -> 2339.76 | C37: ₹/t
A38: Benefit of washing over selling raw | B38: =B37-B31 -> 139.76 | C38: ₹/t | D38: Positive means washing pays.
A39: Break-even washed coal price | B39: =IFERROR((B31+B36-B35)/B33,0) -> 3964.2375 | C39: ₹/t | D39: The washed price at which washing and selling raw earn the same.
A40: Verdict | B40: =IF(B38>0,"Washing pays","Sell raw") -> Washing pays
A41: Selling price used in the model, per tonne of ROM | B41: =IF(Inputs!$B$48=1,B37,B31) -> 2200 | C41: ₹/t | D41: Feeds Economics (coal selling price). Switch on Inputs section 6.
A43: D. Statutory levies on coal (mining legislation)
A44: Item | B44: Value | C44: Unit | D44: What it means
...

Sheet Economics
A1: Economics — cost per tonne, break-even stripping ratio, project value
A2: Costs per unit = machine cost per hour ÷ what the machine produces per hour. Simplified: before tax, constant average stripping ratio.
A4: Item | B4: Value | C4: Unit | D4: What it means
A5: A. Overburden removal cost
A6: Drilling and blasting | B6: =Inputs!$B$35 -> 35 | C6: ₹/BCM | D6: From Inputs.
A7: Excavation | B7: =Inputs!$B$37/Fleet!$B$11 -> 17.867647 | C7: ₹/BCM | D7: Excavator cost per hour ÷ BCM it moves per hour.
A8: Haulage | B8: =Inputs!$B$38/(Fleet!$B$23/Inputs!$B$9) -> 60.693277 | C8: ₹/BCM | D8: Dumper cost per hour ÷ BCM it hauls per hour (tonnes per hour ÷ density).
A9: Overburden removal cost | B9: =SUM(B6:B8) -> 113.56092 | C9: ₹/BCM | D9: Sum of the three above.
A10: B. Coal winning cost (excluding overburden)
A11: Drilling and blasting | B11: =Inputs!$B$36 -> 20 | C11: ₹/t | D11: From Inputs.
A12: Excavation | B12: =Inputs!$B$37/Fleet!$C$12 -> 12.289916 | C12: ₹/t | D12: Excavator cost per hour ÷ coal tonnes per hour.
A13: Haulage | B13: =Inputs!$B$38/Fleet!$C$23 -> 39.92597 | C13: ₹/t | D13: Dumper cost per hour ÷ coal tonnes per hour.
A14: Handling and dispatch | B14: =Inputs!$B$39 -> 150 | C14: ₹/t | D14: From Inputs.
A15: Overheads and site costs | B15: =Inputs!$B$40 -> 600 | C15: ₹/t | D15: From Inputs.
A16: Royalty and levies | B16: ='Quality and royalty'!$B$53 -> 900 | C16: ₹/t | D16: From the Quality and royalty sheet: royalty + DMF + NMET + other levies, or the flat placeholder if the switch on Inputs is 0.
A17: Coal winning cost | B17: =SUM(B11:B16) -> 1722.2159 | C17: ₹/t | D17: Sum of the six lines above.
A18: C. Break-even stripping ratio (the key planning number)
A19: Coal selling price | B19: ='Quality and royalty'!$B$41 -> 2200 | C19: ₹/t | D19: From the Quality and royalty sheet: raw selling price, or net realisation per tonne of ROM coal if washed coal is selected on Inputs.
A20: Margin available to pay for overburden removal | B20: =B19-B17 -> 477.78411 | C20: ₹/t | D20: Price minus coal winning cost.
A21: Break-even stripping ratio | B21: =IF(B9>0,B20/B9,0) -> 4.2072933 | C21: m³/t | D21: Margin ÷ overburden cost per BCM. A block with a higher stripping ratio loses money.
A22: Actual stripping ratio, economic blocks | B22: =Reserve!$B$38 -> 2.9310858 | C22: m³/t | D22: From the Reserve sheet. Includes the pit-slope wedge when the switch on Inputs is 1.
A23: Verdict at the average stripping ratio | B23: =IF(B22<=B21,"Viable on average","Not viable on average") -> Viable on average | D23: Compares actual with break-even.
A24: D. Cost, profit and project value
A25: All-in cost per tonne of coal | B25: =B17+B22*B9 -> 2055.0727 | C25: ₹/t | D25: Coal winning cost + stripping ratio × overburden cost.
A26: Profit per tonne | B26: =B19-B25 -> 144.9273 | C26: ₹/t | D26: Price minus all-in cost (before tax).
A27: Profit margin | B27: =IF(B19>0,B26/B19,0) -> 0.065876046 | C27: % | D27: Profit ÷ price.
A28: Annual production | B28: =Inputs!$B$11 -> 500000 | C28: t/yr | D28: From Inputs.
A29: Annual revenue | B29: =B28*B19/10000000 -> 110 | C29: ₹ crore | D29: 1 crore = 10,000,000.
A30: Annual cost | B30: =B28*B25/10000000 -> 102.75363 | C30: ₹ crore
A31: Annual profit before tax | B31: =B29-B30 -> 7.246365 | C31: ₹ crore
A32: Mine life (economic blocks) | B32: =Reserve!$B$40 -> 3.38744 | C32: years | D32: From the Reserve sheet.
A33: Non-equipment capital cost | B33: =Inputs!$B$43 -> 10 | C33: ₹ crore | D33: From Inputs.
A34: Net present value (NPV) | B34: ='Cash flow'!$B$19 -> 9.9382192 | C34: ₹ crore | D34: From the Cash flow sheet. Positive means the project earns more than the discount rate.

Sheet Cash flow
A1: Cash flow — year by year over the mine life
A2: Production each year = the smaller of the annual target and the coal still left. Profit is discounted back to today's value.
A4: Year | B4: Opening reserve (t) | C4: Production (t) | D4: Closing reserve (t) | E4: Revenue (₹ crore) | F4: Cost (₹ crore) | G4: Cash flow (₹ crore) | H4: Discount factor | I4: Present value (₹ crore)
A5: 1 | B5: =Reserve!$B$39 -> 1693720 | C5: =MIN(Inputs!$B$11,B5) -> 500000 | D5: =B5-C5 -> 1193720 | E5: =C5*Economics!$B$19/10000000 -> 110 | F5: =C5*Economics!$B$25/10000000 -> 102.75363 | G5: =E5-F5 -> 7.246365 | H5: =1/(1+Inputs!$B$44)^A5 -> 0.90909091 | I5: =G5*H5 -> 6.5876046
A6: 2 | B6: =D5 -> 1193720 | C6: =MIN(Inputs!$B$11,B6) -> 500000 | D6: =B6-C6 -> 693720 | E6: =C6*Economics!$B$19/10000000 -> 110 | F6: =C6*Economics!$B$25/10000000 -> 102.75363 | G6: =E6-F6 -> 7.246365 | H6: =1/(1+Inputs!$B$44)^A6 -> 0.82644628 | I6: =G6*H6 -> 5.9887314
